2025-07-04 16:42:33,355 INFO    MainThread:63993 [wandb_init.py:setup_run_log_directory():703] Logging user logs to /Users/jgao/github/ECRI-RCDS-Hackathon/wandb/run-20250704_164233-8zvp8cgx/logs/debug.log
2025-07-04 16:42:33,355 INFO    MainThread:63993 [wandb_init.py:setup_run_log_directory():704] Logging internal logs to /Users/jgao/github/ECRI-RCDS-Hackathon/wandb/run-20250704_164233-8zvp8cgx/logs/debug-internal.log
2025-07-04 16:42:33,355 INFO    MainThread:63993 [wandb_init.py:monkeypatch_ipython():622] configuring jupyter hooks <wandb.sdk.wandb_init._WandbInit object at 0x11cbff7a0>
2025-07-04 16:42:33,355 INFO    MainThread:63993 [wandb_init.py:init():830] calling init triggers
2025-07-04 16:42:33,356 INFO    MainThread:63993 [wandb_init.py:init():835] wandb.init called with sweep_config: {}
config: {'_wandb': {}}
2025-07-04 16:42:33,356 INFO    MainThread:63993 [wandb_init.py:init():871] starting backend
2025-07-04 16:42:33,356 INFO    MainThread:63993 [wandb_init.py:init():874] sending inform_init request
2025-07-04 16:42:33,356 INFO    MainThread:63993 [wandb_init.py:init():882] backend started and connected
2025-07-04 16:42:33,357 INFO    MainThread:63993 [wandb_run.py:_label_probe_notebook():1304] probe notebook
2025-07-04 16:42:33,359 INFO    MainThread:63993 [wandb_init.py:init():953] updated telemetry
2025-07-04 16:42:33,390 INFO    MainThread:63993 [wandb_init.py:init():977] communicating run to backend with 90.0 second timeout
2025-07-04 16:42:33,860 INFO    MainThread:63993 [wandb_init.py:init():1029] starting run threads in backend
2025-07-04 16:42:33,919 INFO    MainThread:63993 [wandb_run.py:_console_start():2458] atexit reg
2025-07-04 16:42:33,920 INFO    MainThread:63993 [wandb_run.py:_redirect():2306] redirect: wrap_raw
2025-07-04 16:42:33,920 INFO    MainThread:63993 [wandb_run.py:_redirect():2375] Wrapping output streams.
2025-07-04 16:42:33,920 INFO    MainThread:63993 [wandb_run.py:_redirect():2398] Redirects installed.
2025-07-04 16:42:33,920 INFO    MainThread:63993 [wandb_init.py:init():1075] run started, returning control to user process
2025-07-04 16:44:05,400 WARNING MsgRouterThr:63993 [router.py:message_loop():63] [no run ID] message_loop has been closed
Traceback (most recent call last):
  File "/opt/homebrew/lib/python3.13/site-packages/wandb/sdk/interface/router_sock.py", line 27, in _read_message
    return self._sock_client.read_server_response(timeout=1)
           ~~~~~~~~~~~~~~~~~~~~~~~~~~~~~~~~~~~~~~^^^^^^^^^^^
  File "/opt/homebrew/lib/python3.13/site-packages/wandb/sdk/lib/sock_client.py", line 231, in read_server_response
    data = self._read_packet_bytes(timeout=timeout)
  File "/opt/homebrew/lib/python3.13/site-packages/wandb/sdk/lib/sock_client.py", line 216, in _read_packet_bytes
    raise SockClientClosedError
wandb.sdk.lib.sock_client.SockClientClosedError

The above exception was the direct cause of the following exception:

Traceback (most recent call last):
  File "/opt/homebrew/lib/python3.13/site-packages/wandb/sdk/interface/router.py", line 56, in message_loop
    msg = self._read_message()
  File "/opt/homebrew/lib/python3.13/site-packages/wandb/sdk/interface/router_sock.py", line 29, in _read_message
    raise MessageRouterClosedError from e
wandb.sdk.interface.router.MessageRouterClosedError
2025-07-04 16:44:05,410 INFO    MsgRouterThr:63993 [mailbox.py:close():129] [no run ID] Closing mailbox, abandoning 11 handles.
2025-07-04 16:44:05,538 INFO    MainThread:63993 [wandb_init.py:_post_run_cell_hook():592] [no run ID] resuming backend
2025-07-04 16:45:10,225 INFO    MainThread:63993 [jupyter.py:save_ipynb():404] [no run ID] not saving jupyter notebook
2025-07-04 16:45:10,226 INFO    MainThread:63993 [wandb_init.py:_pre_run_cell_hook():581] [no run ID] pausing backend
2025-07-04 16:45:10,261 INFO    MainThread:63993 [wandb_init.py:_post_run_cell_hook():592] [no run ID] resuming backend
2025-07-04 16:45:10,289 INFO    MainThread:63993 [jupyter.py:save_ipynb():404] [no run ID] not saving jupyter notebook
2025-07-04 16:45:10,290 INFO    MainThread:63993 [wandb_init.py:_pre_run_cell_hook():581] [no run ID] pausing backend
2025-07-04 16:45:10,311 INFO    MainThread:63993 [wandb_init.py:_post_run_cell_hook():592] [no run ID] resuming backend
2025-07-04 16:45:10,344 INFO    MainThread:63993 [jupyter.py:save_ipynb():404] [no run ID] not saving jupyter notebook
2025-07-04 16:45:10,345 INFO    MainThread:63993 [wandb_init.py:_pre_run_cell_hook():581] [no run ID] pausing backend
2025-07-04 16:45:10,370 INFO    MainThread:63993 [wandb_run.py:_finish():2224] finishing run jl-liam-gao/network_analysis/8zvp8cgx
2025-07-04 16:45:10,370 ERROR   MainThread:63993 [wandb_init.py:init():1616] [no run ID] error in wandb.init()
Traceback (most recent call last):
  File "/opt/homebrew/lib/python3.13/site-packages/wandb/sdk/wandb_init.py", line 1606, in init
    return wi.init(run_settings, run_config, run_printer)
           ~~~~~~~^^^^^^^^^^^^^^^^^^^^^^^^^^^^^^^^^^^^^^^
  File "/opt/homebrew/lib/python3.13/site-packages/wandb/sdk/wandb_init.py", line 851, in init
    self._wl.finish_all_active_runs()
    ~~~~~~~~~~~~~~~~~~~~~~~~~~~~~~~^^
  File "/opt/homebrew/lib/python3.13/site-packages/wandb/sdk/wandb_setup.py", line 161, in finish_all_active_runs
    run.finish()
    ~~~~~~~~~~^^
  File "/opt/homebrew/lib/python3.13/site-packages/wandb/sdk/wandb_run.py", line 398, in wrapper
    return func(self, *args, **kwargs)
  File "/opt/homebrew/lib/python3.13/site-packages/wandb/sdk/wandb_run.py", line 443, in wrapper
    return func(self, *args, **kwargs)
  File "/opt/homebrew/lib/python3.13/site-packages/wandb/sdk/wandb_run.py", line 2212, in finish
    return self._finish(exit_code)
           ~~~~~~~~~~~~^^^^^^^^^^^
  File "/opt/homebrew/lib/python3.13/site-packages/wandb/sdk/wandb_run.py", line 398, in wrapper
    return func(self, *args, **kwargs)
  File "/opt/homebrew/lib/python3.13/site-packages/wandb/sdk/wandb_run.py", line 2225, in _finish
    with telemetry.context(run=self) as tel:
         ~~~~~~~~~~~~~~~~~^^^^^^^^^^
  File "/opt/homebrew/lib/python3.13/site-packages/wandb/sdk/lib/telemetry.py", line 42, in __exit__
    self._run._telemetry_callback(self._obj)
    ~~~~~~~~~~~~~~~~~~~~~~~~~~~~~^^^^^^^^^^^
  File "/opt/homebrew/lib/python3.13/site-packages/wandb/sdk/wandb_run.py", line 764, in _telemetry_callback
    self._telemetry_flush()
    ~~~~~~~~~~~~~~~~~~~~~^^
  File "/opt/homebrew/lib/python3.13/site-packages/wandb/sdk/wandb_run.py", line 777, in _telemetry_flush
    self._backend.interface._publish_telemetry(self._telemetry_obj)
    ~~~~~~~~~~~~~~~~~~~~~~~~~~~~~~~~~~~~~~~~~~^^^^^^^^^^^^^^^^^^^^^
  File "/opt/homebrew/lib/python3.13/site-packages/wandb/sdk/interface/interface_shared.py", line 60, in _publish_telemetry
    self._publish(rec)
    ~~~~~~~~~~~~~^^^^^
  File "/opt/homebrew/lib/python3.13/site-packages/wandb/sdk/interface/interface_sock.py", line 39, in _publish
    self._sock_client.send_record_publish(record)
    ~~~~~~~~~~~~~~~~~~~~~~~~~~~~~~~~~~~~~^^^^^^^^
  File "/opt/homebrew/lib/python3.13/site-packages/wandb/sdk/lib/sock_client.py", line 170, in send_record_publish
    self.send_server_request(server_req)
    ~~~~~~~~~~~~~~~~~~~~~~~~^^^^^^^^^^^^
  File "/opt/homebrew/lib/python3.13/site-packages/wandb/sdk/lib/sock_client.py", line 150, in send_server_request
    self._send_message(msg)
    ~~~~~~~~~~~~~~~~~~^^^^^
  File "/opt/homebrew/lib/python3.13/site-packages/wandb/sdk/lib/sock_client.py", line 147, in _send_message
    self._sendall_with_error_handle(header + data)
    ~~~~~~~~~~~~~~~~~~~~~~~~~~~~~~~^^^^^^^^^^^^^^^
  File "/opt/homebrew/lib/python3.13/site-packages/wandb/sdk/lib/sock_client.py", line 126, in _sendall_with_error_handle
    sent = self._sock.send(data)
BrokenPipeError: [Errno 32] Broken pipe
2025-07-04 16:45:10,615 INFO    MainThread:63993 [wandb_init.py:_post_run_cell_hook():592] [no run ID] resuming backend
2025-07-04 16:45:24,198 INFO    MainThread:63993 [jupyter.py:save_ipynb():404] [no run ID] not saving jupyter notebook
2025-07-04 16:45:24,199 INFO    MainThread:63993 [wandb_init.py:_pre_run_cell_hook():581] [no run ID] pausing backend
2025-07-04 16:45:24,242 INFO    MainThread:63993 [wandb_init.py:_post_run_cell_hook():592] [no run ID] resuming backend
2025-07-04 16:45:24,274 INFO    MainThread:63993 [jupyter.py:save_ipynb():404] [no run ID] not saving jupyter notebook
2025-07-04 16:45:24,274 INFO    MainThread:63993 [wandb_init.py:_pre_run_cell_hook():581] [no run ID] pausing backend
2025-07-04 16:45:24,293 INFO    MainThread:63993 [wandb_init.py:_post_run_cell_hook():592] [no run ID] resuming backend
2025-07-04 16:45:24,311 INFO    MainThread:63993 [jupyter.py:save_ipynb():404] [no run ID] not saving jupyter notebook
2025-07-04 16:45:24,312 INFO    MainThread:63993 [wandb_init.py:_pre_run_cell_hook():581] [no run ID] pausing backend
2025-07-04 16:45:24,332 INFO    MainThread:63993 [wandb_run.py:_finish():2224] finishing run jl-liam-gao/network_analysis/8zvp8cgx
2025-07-04 16:45:24,332 ERROR   MainThread:63993 [wandb_init.py:init():1616] [no run ID] error in wandb.init()
Traceback (most recent call last):
  File "/opt/homebrew/lib/python3.13/site-packages/wandb/sdk/wandb_init.py", line 1606, in init
    return wi.init(run_settings, run_config, run_printer)
           ~~~~~~~^^^^^^^^^^^^^^^^^^^^^^^^^^^^^^^^^^^^^^^
  File "/opt/homebrew/lib/python3.13/site-packages/wandb/sdk/wandb_init.py", line 851, in init
    self._wl.finish_all_active_runs()
    ~~~~~~~~~~~~~~~~~~~~~~~~~~~~~~~^^
  File "/opt/homebrew/lib/python3.13/site-packages/wandb/sdk/wandb_setup.py", line 161, in finish_all_active_runs
    run.finish()
    ~~~~~~~~~~^^
  File "/opt/homebrew/lib/python3.13/site-packages/wandb/sdk/wandb_run.py", line 398, in wrapper
    return func(self, *args, **kwargs)
  File "/opt/homebrew/lib/python3.13/site-packages/wandb/sdk/wandb_run.py", line 443, in wrapper
    return func(self, *args, **kwargs)
  File "/opt/homebrew/lib/python3.13/site-packages/wandb/sdk/wandb_run.py", line 2212, in finish
    return self._finish(exit_code)
           ~~~~~~~~~~~~^^^^^^^^^^^
  File "/opt/homebrew/lib/python3.13/site-packages/wandb/sdk/wandb_run.py", line 398, in wrapper
    return func(self, *args, **kwargs)
  File "/opt/homebrew/lib/python3.13/site-packages/wandb/sdk/wandb_run.py", line 2225, in _finish
    with telemetry.context(run=self) as tel:
         ~~~~~~~~~~~~~~~~~^^^^^^^^^^
  File "/opt/homebrew/lib/python3.13/site-packages/wandb/sdk/lib/telemetry.py", line 42, in __exit__
    self._run._telemetry_callback(self._obj)
    ~~~~~~~~~~~~~~~~~~~~~~~~~~~~~^^^^^^^^^^^
  File "/opt/homebrew/lib/python3.13/site-packages/wandb/sdk/wandb_run.py", line 764, in _telemetry_callback
    self._telemetry_flush()
    ~~~~~~~~~~~~~~~~~~~~~^^
  File "/opt/homebrew/lib/python3.13/site-packages/wandb/sdk/wandb_run.py", line 777, in _telemetry_flush
    self._backend.interface._publish_telemetry(self._telemetry_obj)
    ~~~~~~~~~~~~~~~~~~~~~~~~~~~~~~~~~~~~~~~~~~^^^^^^^^^^^^^^^^^^^^^
  File "/opt/homebrew/lib/python3.13/site-packages/wandb/sdk/interface/interface_shared.py", line 60, in _publish_telemetry
    self._publish(rec)
    ~~~~~~~~~~~~~^^^^^
  File "/opt/homebrew/lib/python3.13/site-packages/wandb/sdk/interface/interface_sock.py", line 39, in _publish
    self._sock_client.send_record_publish(record)
    ~~~~~~~~~~~~~~~~~~~~~~~~~~~~~~~~~~~~~^^^^^^^^
  File "/opt/homebrew/lib/python3.13/site-packages/wandb/sdk/lib/sock_client.py", line 170, in send_record_publish
    self.send_server_request(server_req)
    ~~~~~~~~~~~~~~~~~~~~~~~~^^^^^^^^^^^^
  File "/opt/homebrew/lib/python3.13/site-packages/wandb/sdk/lib/sock_client.py", line 150, in send_server_request
    self._send_message(msg)
    ~~~~~~~~~~~~~~~~~~^^^^^
  File "/opt/homebrew/lib/python3.13/site-packages/wandb/sdk/lib/sock_client.py", line 147, in _send_message
    self._sendall_with_error_handle(header + data)
    ~~~~~~~~~~~~~~~~~~~~~~~~~~~~~~~^^^^^^^^^^^^^^^
  File "/opt/homebrew/lib/python3.13/site-packages/wandb/sdk/lib/sock_client.py", line 126, in _sendall_with_error_handle
    sent = self._sock.send(data)
BrokenPipeError: [Errno 32] Broken pipe
2025-07-04 16:45:24,452 INFO    MainThread:63993 [wandb_init.py:_post_run_cell_hook():592] [no run ID] resuming backend
